Workbook

Sheet 1
I4: KEMENTRIAN KEUANGAN | Y4: SPT TAHUNAN | AP4: INDUK
I5: REPUBLIK INDONESIA | Y5: PAJAK PENGHASILAN (PPh) | AP5: HALAMAN 1
I6: DIREKTORAT JENDERAL PAJAK | Y6: WAJIB PAJAK ORANG PRIBADI
E9: TAHUN PAJAK/BAGIAN TAHUN PAJAK | O9: PERIODE | V9: STATUS | AC9: SUMBER PENGHASILAN | AK9: METODE PEMBUKUAN
G10: TAHUN PAJAK | O10: BULAN MULAI | R10: BULAN AKHIR | X10: NORMAL | AE10: PEKERJAAN | AM10: PEMBUKUAN STELSEL AKRUAL
G12: BAGIAN TAHUN PAJAK | X12: PEMBETULAN | AE12: KEGIATAN USAHA | AM12: PEMBUKUAN STELSEL KAS
Q14: S.D | AE14: PEKERJAAN BEBAS | AM14: PENCATATAN
D18: A. | E18: IDENTITAS WAJIB PAJAK
E21: 1. | F21: NIK/NPWP | AB21: 7. | AC21: STATUS KEWAJIBAN PERPAJAKAN SUAMI DAN ISTRI
E23: 2. | F23: NAMA | AD23: PISAH HARTA | AK23: MEMILIH TERPISAH
E25: 3. | F25: JENIS ID | K25: KTP | O25: KITAS | S25: PASPOR | AC25: (Jika status kewajiban perpajakan Anda dengan pasangan adalah PH atau MT, Anda diwajibkan mengisi bagian ini dan Lampiran 4 Bagian B)
E27: 4. | F27: NO. ID
E29: 5. | F29: NO. TELEPON | AB29: 8. | AC29: NIK/NPWP SUAMI/ISTRI*
E31: 6. | F31: EMAIL
D34: B. | E34: IKHTISAR PENGHASILAN NETO
E36: 1 | F36: a | G36: APAKAH ANDA MENERIMA PENGHASILAN DALAM NEGERI DARI PEKERJAAN ? | AL36: ='L1-3'!AJ36 -> 0
I37: Tidak. (Lanjut ke pertanyaan selanjutnya)
I38: Ya. (Isi Lampiran 1 Bagian D lalu ke pertanyaan selanjutnya)
F40: b | G40: 1) | H40: APAKAH ANDA MENERIMA PENGHASILAN DALAM NEGERI DARI USAHA DAN/ATAU PEKERJAAN BEBAS ?
I41: Tidak. (Lanjut ke pertanyaan 1c)
I42: Ya. (Lanjut ke pertanyaan selanjutnya)
G44: 2) | H44: APAKAH ANDA TERMASUK WAJIB PAJAK ORANG PRIBADI YANG MEMILIKI PEREDARAN BRUTO TERTENTU ATAU ORANG PRIBADI PENGUSAHA TERTENTU (OPPT) ?
I46: Tidak. (Lanjut ke pertanyaan selanjutnya)
I47: Ya, saya termasuk Wajib Pajak Orang Pribadi yang memiliki Peredaran Bruto Tertentu yang dikenai Pajak bersifat Final. (Isi Lampiran 3B Bagian A. lalu ke pertanyaan selanjutnya)
I49: Ya, saya termasuk Wajib Pajak OPPT. (Isi Lampiran 3B Bagian B, lalu ke pertanyaan selanjutnya)
G51: 3) | H51: APAKAH ANDA MENGGUNAKAN NORMA DALAM MENGHITUNG PENGHASILAN NETO ?
I52: Tidak, saya menyelenggarakan pembukuan (Lanjut ke pertanyaan selanjutnya)
I53: Tidak, saya hanya menerima penghasilan dari usaha yang dikenakan pajak bersifat final dan tidak menyelenggarakan pembukuan. (Lanjut ke pertanyaan 1c)
I55: Ya, saya berhak menggunakan Norma Penghitungan Penghasilan Neto.
I56: (Isi Lampiran 3B Bagian C, Lampiran 3A-4 Bagian A, lalu ke pertanyaan 1c)
G58: 4) | H58: ANDA MENYELENGGARAKAN PEMBUKUAN. SEBUTKAN SEKTOR USAHA YANG ANDA LAKUKAN.
I59: Dagang. (Isi Lampiran 3A-1, lalu ke pertanyaan selanjutnya)
I60: Jasa. (Isi Lampiran 3A-2, lalu ke pertanyaan selanjutnya)
I61: Industri. (Isi Lampiran 3A-3, lalu ke pertanyaan selanjutnya)
G63: 5) | H63: PENGHASILAN NETO DARI USAHA DAN/ATAU PEKERJAAN BEBAS | AL63: ='L3A-4'!AJ27 -> 0
F65: c | G65: APAKAH ANDA MENERIMA PENGHASILAN DALAM NEGERI LAINNYA ? | AL65: ='L3A-4'!AE54 -> 0
I66: Tidak. (Lanjut ke pertanyaan selanjutnya).
I67: Ya. (Isi Lampiran 3A-4 Bagian B lalu ke pertanyaan selanjutnya)
F69: d | G69: APAKAH ANDA MENERIMA PENGHASILAN LUAR NEGERI ? | AL69: ='L2'!T73 -> 0
I70: Tidak. (Lanjut ke pertanyaan selanjutnya).
...

Sheet 2
I4: KEMENTRIAN KEUANGAN | Y4: SPT TAHUNAN | AP4: INDUK
I5: REPUBLIK INDONESIA | Y5: PAJAK PENGHASILAN (PPh) | AP5: HALAMAN 2
I6: DIREKTORAT JENDERAL PAJAK | Y6: WAJIB PAJAK ORANG PRIBADI
D9: E. | E9: PPh KURANG /LEBIH BAYAR
E11: 11 | F11: a | G11: PPh KURANG/LEBIH BAYAR | X11: ( | Y11: 9 | Z11: - | AA11: 10a | AB11: - | AC11: 10b | AD11: - | AE11: 10c | AF11: + | AG11: 10d | AH11: ) | AL11: ='1'!AL94-'1'!AL98-'1'!AL102-'1'!AL104+'1'!AL106 -> 23750000
F13: b | G13: APAKAH TERDAPAT SURAT KEPUTUSAN PERSETUJUAN PENGANGSURAN ATAU PENUNDAAN PEMBAYARAN PAJAK ?
I14: Tidak, saya tidak memilikinya. (Lanjut ke pertanyaan selanjutnya).
I15: Ya, saya memilikinya. (Isi dengan jumlah yang telah disetujui untuk diangsur/ditunda, lalu kepertanyaan selanjutnya)
F17: c | G17: PPh YANG MASIH HARUS DIBAYAR | X17: ( | Y17: 11a | Z17: - | AA17: 11b | AB17: ) | AL17: =AL11-AL13 -> 23750000
D19: F. | E19: PEMBETULAN (DIISI JIKA STATUS SPT ADALAH PEMBETULAN)
E21: 12 | F21: a | G21: PPH KURANG /LEBIH BAYAR PADA SPT YANG DIBETULKAN | Z21: GANTI SPT SEBELUMNYA
F23: b | G23: PPH KURANG /LEBIH BAYAR KARENA PEMBETULAN | X23: ( | Y23: 11a | Z23: - | AA23: 12a | AB23: ) | AL23: 0
D25: G. | E25: PERMOHONAN PENGEMBALIAN PPh LEBIH BAYAR (DIISI JIKA STATUS SPT ADALAH LEBIH BAYAR)
E27: PPh LEBIH BAYAR PADA 11a ATAU 12b MOHON : | V27: NOMOR REKENING | AK27: NAMA BANK
G29: Dikembalikan melalui pemeriksaan.
G30: Dikembalikan melalui permhonan pengembalian pendahuluan | V30: NAMA PEMILIK REKENING
D32: H. | E32: ANGSURAN PPh PASAL 25 TAHUN PAJAK BERIKUTNYA
E34: 13 | F34: a | G34: APAKAH ANDA HANYA MENERIMA PENGHASILAN TERATUR DAN BERKEWAJIBAN MEMBAYAR ANGSURAN PPh PASAL 25 TAHUN PAJAK BERIKUTNYA ? | AL34: =(1/Y37*('1'!AL94-'1'!AL98)) -> 2979166.7
I36: Tidak. (Lanjut ke pertanyaan selanjutnya).
I37: Ya, angsuran PPh Pasal 25-nya adalah | X37: (1/ | Y37: 12 | Z37: X | AA37: ( | AB37: 9 | AC37: - | AD37: 10a | AE37: )
F39: b | G39: APAKAH ANDA MENYUSUN PERHITUNGAN TERSENDIRI ANGUSRAN PPh PASAL 25 TAHUN PAJAK BERIKUTNYA ?
I40: Tidak. (Lanjut ke pertanyaan selanjutnya).
I41: Ya. (Isi Lampiran 4 Bagian A)
F43: c | G43: APAKAH ANDA MEMBAYAR ANGSURAN PPh PASAL 25 OPPT TAHUN PAJAK BERIUKUTNYA ?
I44: Tidak, saya tidak memliki kewajiban untuk membayar angsuran PPh Pasal 25.
I45: Ya, angsuran PPh Pasal 25 saya adalah 0,75 % dari penghasilan bruto setiap bulan dari masing-masing tempat usaha.
D47: I. | E47: PERNYATAAN TRANSAKSI LAINNYA
E49: 14 | F49: a | G49: HARTA PADA AKHIR TAHUN PAJAK (Isi Lampiran 1 Bagian A) | AL49: ='L1-2'!P60 -> 0
F51: b | G51: APAKAH ANDA MEMILIKI UTANG PADA AKHIR TAHUN PAJAK ? | AL51: ='L1-2'!AD82 -> 0
I52: Tidak. (Lanjut ke pertanyaan selanjutnya).
I53: Ya. (Isi Lampiran 1 Bagian B, lalu ke pertanyaan selanjutnya)
F55: c | G55: APAKAH ANDA MENERIMA PENGHASILAN YANG DIKENAKAN PAJAK PENGHASILAN BERSIFAT FINAL ?
I56: Tidak. (Lanjut ke pertanyaan selanjutnya).
I57: Ya. (Isi Lampiran 2 Bagian A, lalu ke pertanyaan selanjutnya)
F59: d | G59: APAKAH ANDA MENERIMA PENGHASILAN YANG TIDAK TERMASUK OBJEK PAJAK ? | AL59: ='L2'!AL57 -> 0
I60: Tidak. (Lanjut ke pertanyaan selanjutnya).
I61: Ya. (Isi Lampiran 2 Bagian B, lalu ke pertanyaan selanjutnya)
F63: e | G63: APAKAH ANDA MELAPORKAN BIAYA PENYUSUTAN DAN/ATAU AMORTISASI FISKAL ?
I64: Tidak. (Lanjut ke pertanyaan selanjutnya).
I65: Ya. (Isi Lampiran 3 C, lalu ke pertanyaan selanjutnya)
...

Sheet L1-1
D4: PERHATIAN: | N4: A. | O4: HARTA PADA AKHIR TAHUN PAJAK | AM4: LAMPIRAN 1
D5: LAMPIRAN INI DIISI OLEH WAJIB PAJAK UNTUK MELAPORKAN HARTA, UTANG, DAFTAR ANGGOTA KELUARGA YANG MENJADI TANGGUNGAN, PENGHASILAN NETO DALAM NEGERI DARI PEKERJAAN DAN/ATAU BUKTI PEMOTONGAN PEMUNGUTAN PPh | N5: B. | O5: UTANG PADA AKHIR TAHUN PAJAK
N6: C. | O6: DAFTAR ANGGOTA KELUARGA YANG MENJADI TANGGUNGAN | AM6: HALAMAN 1
N7: D. | O7: PENGHASILAN NETO DALAM NEGERI DAN PEKERJAAN
N8: E. | O8: DAFTAR BUKTI PEMOTONGAN/PEMUNGUTAN PPh
N9: NIK/NPWP | Q9: ='1'!J21 | R9: ='1'!K21 | S9: ='1'!L21 | T9: ='1'!M21 | U9: ='1'!N21 | V9: ='1'!O21 | W9: ='1'!P21 | X9: ='1'!Q21 | ... AF9: ='1'!Y21 | AM9: TAHUN PAJAK | AQ9: ='1'!E14 | AR9: ='1'!G14 | AS9: ='1'!I14 | AT9: ='1'!K14
C12: A. | D12: HARTA PADA AKHIR TAHUN PAJAK
C14: 1. | D14: KAS DAN SETARA KAS
C16: KODE | F16: DESKRIPSI | K16: NOMOR AKUN | O16: ATAS NAMA | T16: NAMA BANK/INSTITUSI | Z16: LOKASI HARTA | AE16: TAHUN PEROLEHAN | AI16: SALDO | AN16: KETERANGAN
AN17: (Harta PPS/Harta Investasi PPS) | AW17: - | AX17: -
C18: (1) | F18: (2) | K18: (3) | O18: (4) | T18: (5) | Z18: (6) | AE18: (7) | AI18: (8) | AN18: (9) | AW18: 0101 | AX18: UANG TUNAI/BANK NOTE/KOIN
C19: - | F19: =VLOOKUP(C19,$AW$17:$AX$26,2,FALSE()) -> - | AN19: - | AW19: 0102 | AX19: TABUNGAN (BANK/LEMBAGA KEUANGAN)
C20: - | F20: =VLOOKUP(C20,$AW$17:$AX$26,2,FALSE()) -> - | AW20: 0103 | AX20: GIRO
C21: - | F21: =VLOOKUP(C21,$AW$17:$AX$26,2,FALSE()) -> - | AW21: 0104 | AX21: DEPOSITO
C22: - | F22: =VLOOKUP(C22,$AW$17:$AX$26,2,FALSE()) -> - | AW22: 0105 | AX22: UANG ELEKTRONIK
C23: - | F23: =VLOOKUP(C23,$AW$17:$AX$26,2,FALSE()) -> - | AW23: 0106 | AX23: CEK
C24: - | F24: =VLOOKUP(C24,$AW$17:$AX$26,2,FALSE()) -> - | AW24: 0107 | AX24: WESSEL
C25: - | F25: =VLOOKUP(C25,$AW$17:$AX$26,2,FALSE()) -> - | AW25: 0108 | AX25: KERTAS KOMERSIAL
C26: JUMLAH TABEL 1 | AG26: 1 | AI26: =SUM(AI19:AI25) -> 0 | AW26: 0109 | AX26: SETARA KAS LAINNYA
C28: 2. | D28: PIUTANG
C30: KODE | F30: DESKRIPSI | K30: LOKASI PENERIMAPINJAMAN | O30: PENERIMA PINJAMAN | Z30: NILAI PIUTANG | AE30: TAHUN DIMULAI | AI30: SALDO PIUTANG SAAT INI | AN30: KETERANGAN
AN31: (Harta PPS/Harta Investasi PPS)
C33: (1) | F33: (2) | K33: (3) | O33: (4) | Z33: (5) | AE33: (6) | AI33: (7) | AN33: (8) | AW33: - | AX33: -
C34: - | F34: =VLOOKUP(C34,$AW$33:$AX$36,2,FALSE()) -> - | O34: NIK/NPWP | AW34: 0201 | AX34: PIUTANG USAHA
O35: NAMA | AW35: 0202 | AX35: PIUTANG AFILIASI
C36: - | F36: =VLOOKUP(C36,$AW$33:$AX$36,2,FALSE()) -> - | O36: NIK/NPWP | AW36: 0209 | AX36: PIUTANG LAINNYA
O37: NAMA
C38: - | F38: =VLOOKUP(C38,$AW$33:$AX$36,2,FALSE()) -> - | O38: NIK/NPWP
O39: NAMA
C40: - | F40: =VLOOKUP(C40,$AW$33:$AX$36,2,FALSE()) -> - | O40: NIK/NPWP
O41: NAMA
C42: - | F42: =VLOOKUP(C42,$AW$33:$AX$36,2,FALSE()) -> - | O42: NIK/NPWP
O43: NAMA
C44: JUMLAH TABEL 2 | AG44: 2 | AI44: =SUM(AI34:AM43) -> 0
C46: 3. | D46: INVESTASI/SEKURITAS
C48: KODE | F48: DESKRIPSI | K48: LOKASI HARTA | O48: BANK / INSTITUSI / PENERIMA INVESTASI | X48: NOMOR AKUN | AB48: HARGA PEROLEHAN | AG48: TAHUN PEROLEHAN | AK48: NILAI SAAT INI | AO48: KETERANGAN | AW48: - | AX48: -
AO49: =AN31 -> (Harta PPS/Harta Investasi PPS) | AW49: 0301 | AX49: SAHAM YANG DIBELI UNTUK DIJUAL KEMBALI
AW50: 0302 | AX50: SAHAM NON BURSA
C51: (1) | F51: (2) | K51: (3) | O51: (4) | X51: (5) | AB51: (6) | AG51: (7) | AK51: (8) | AO51: (9) | AW51: 0303 | AX51: SAHAM BURSA
C52: - | F52: =VLOOKUP(C52,$AW$48:$AX$60,2,FALSE()) -> - | O52: NPWP | AO52: - | AW52: 0304 | AX52: OBLIGASI PERUSAHAAN
...

Sheet L1-2
D4: PERHATIAN: | N4: A. | O4: HARTA PADA AKHIR TAHUN PAJAK | AM4: LAMPIRAN 1
D5: LAMPIRAN INI DIISI OLEH WAJIB PAJAK UNTUK MELAPORKAN HARTA, UTANG, DAFTAR ANGGOTA KELUARGA YANG MENJADI TANGGUNGAN, PENGHASILAN NETO DALAM NEGERI DARI PEKERJAAN DAN/ATAU BUKTI PEMOTONGAN PEMUNGUTAN PPh | N5: B. | O5: UTANG PADA AKHIR TAHUN PAJAK
N6: C. | O6: DAFTAR ANGGOTA KELUARGA YANG MENJADI TANGGUNGAN | AM6: HALAMAN 2
N7: D. | O7: PENGHASILAN NETO DALAM NEGERI DAN PEKERJAAN
N8: E. | O8: DAFTAR BUKTI PEMOTONGAN/PEMUNGUTAN PPh
N9: NIK/NPWP | Q9: ='1'!J21 | R9: ='1'!K21 | S9: ='1'!L21 | T9: ='1'!M21 | U9: ='1'!N21 | V9: ='1'!O21 | W9: ='1'!P21 | X9: ='1'!Q21 | ... AF9: ='1'!Y21 | AM9: TAHUN PAJAK | AQ9: ='1'!E14 | AR9: ='1'!G14 | AS9: ='1'!I14 | AT9: ='1'!K14
C12: A. | D12: HARTA PADA AKHIR TAHUN PAJAK
C14: 5. | D14: HARTA TIDAK BERGERAK
C16: KODE | E16: DESKRIPSI | I16: LOKASI HARTA | M16: UKURAN PROPERTI | R16: SUMBER KEPEMILIKAN | W16: NOMOR SERTIPIKAT | AB16: TAHUN PEROLEHAN | AF16: HARGA PEROLEHAN | AJ16: NILAI SAAT INI | AN16: KETERANGAN
AN17: (Harta PPS/Harta Investasi PPS)
C18: (1) | E18: (2) | I18: (3) | M18: (4) | R18: (5) | W18: (6) | AB18: (7) | AF18: (8) | AJ18: (9) | AN18: (10) | AW18: - | AX18: -
C19: - | E19: =VLOOKUP(C19,$AW$18:$AX$26,2,FALSE()) -> - | M19: TANAH: | AW19: 0501 | AX19: TANAH KOSONG
M20: BANGUNAN: | AW20: 0502 | AX20: TANAH DAN/ATAU BANGUNAN UNTUK TEMPAT TINGGAL
C21: - | E21: =VLOOKUP(C21,$AW$18:$AX$26,2,FALSE()) -> - | M21: TANAH: | AW21: 0503 | AX21: APARTEMEN
M22: BANGUNAN: | AW22: 0504 | AX22: VESSEL
C23: - | E23: =VLOOKUP(C23,$AW$18:$AX$26,2,FALSE()) -> - | M23: TANAH: | AW23: 0505 | AX23: TANAH ATAU LAHAN UNTUK USAHA (LAHAN PERTANIAN, PERKEBUNAN, DSB)
M24: BANGUNAN: | AW24: 0506 | AX24: TANAH DAN/ATAU BANGUNAN UNTUK USAHA (TOKO, PABRIK, DSB)
C25: - | E25: =VLOOKUP(C25,$AW$18:$AX$26,2,FALSE()) -> - | M25: TANAH: | AW25: 0507 | AX25: TANAH DAN/ATAU BANGUNAN YANG DISEWAKAN
M26: BANGUNAN: | AW26: 0509 | AX26: HARTA TIDAK BERGERAK LAINNYA
C27: - | E27: =VLOOKUP(C27,$AW$18:$AX$26,2,FALSE()) -> - | M27: TANAH:
M28: BANGUNAN:
C29: - | E29: =VLOOKUP(C29,$AW$18:$AX$26,2,FALSE()) -> - | M29: TANAH:
M30: BANGUNAN:
C31: JUMLAH TABEL 5 | AD31: 5 | AF31: =SUM(AF19:AF29) -> 0 | AJ31: =SUM(AJ19:AJ29) -> 0
C33: 6. | D33: HARTA LAINNYA
C35: KODE | E35: DESKRIPSI | O35: TAHUN PEROLEHAN | S35: BUKTI KEPEMILIKAN/NOMOR AKUN | Z35: INFORMASI TAMBAHAN | AF35: HARGA PEROLEHAN | AJ35: NILAI SAAT INI | AN35: KETERANGAN
AN36: (Harta PPS/Harta Investasi PPS)
C38: (1) | E38: (2) | O38: (3) | S38: (4) | Z38: (5) | AF38: (6) | AJ38: (7) | AN38: (8) | AW38: - | AX38: -
C39: - | E39: =VLOOKUP(C39,$AW$38:$AX$55,2,FALSE()) -> - | AW39: 0601 | AX39: PATEN
C40: - | E40: =VLOOKUP(C40,$AW$38:$AX$55,2,FALSE()) -> - | AW40: 0602 | AX40: ROYALTI
C41: - | E41: =VLOOKUP(C41,$AW$38:$AX$55,2,FALSE()) -> - | AW41: 0603 | AX41: MEREK DAGANG
C42: - | E42: =VLOOKUP(C42,$AW$38:$AX$55,2,FALSE()) -> - | AW42: 0699 | AX42: HARTA TIDAK BERWUJUD LAINNYA
C43: - | E43: =VLOOKUP(C43,$AW$38:$AX$55,2,FALSE()) -> - | AW43: 0701 | AX43: EMAS BATANGAN
C44: - | E44: =VLOOKUP(C44,$AW$38:$AX$55,2,FALSE()) -> - | AW44: 0702 | AX44: EMAS PERHIASAN
C45: - | E45: =VLOOKUP(C45,$AW$38:$AX$55,2,FALSE()) -> - | AW45: 0703 | AX45: BATANGAN NON EMAS
C46: - | E46: =VLOOKUP(C46,$AW$38:$AX$55,2,FALSE()) -> - | AW46: 0704 | AX46: PERHIASAN NON EMAS
C47: - | E47: =VLOOKUP(C47,$AW$38:$AX$55,2,FALSE()) -> - | AW47: 0705 | AX47: PERMATA
C48: - | E48: =VLOOKUP(C48,$AW$38:$AX$55,2,FALSE()) -> - | AW48: 0706 | AX48: BARANG-BARANG SENI DAN ANTIK
C49: - | E49: =VLOOKUP(C49,$AW$38:$AX$55,2,FALSE()) -> - | AW49: 0707 | AX49: PERALATAN OLAH RAGA KHUSUS
C50: - | E50: =VLOOKUP(C50,$AW$38:$AX$55,2,FALSE()) -> - | AW50: 0708 | AX50: PERALATAN ELEKTRONIK
...

Sheet L1-3
D4: PERHATIAN: | N4: A. | O4: HARTA PADA AKHIR TAHUN PAJAK | AM4: LAMPIRAN 1
D5: LAMPIRAN INI DIISI OLEH WAJIB PAJAK UNTUK MELAPORKAN HARTA, UTANG, DAFTAR ANGGOTA KELUARGA YANG MENJADI TANGGUNGAN, PENGHASILAN NETO DALAM NEGERI DARI PEKERJAAN DAN/ATAU BUKTI PEMOTONGAN PEMUNGUTAN PPh | N5: B. | O5: UTANG PADA AKHIR TAHUN PAJAK
N6: C. | O6: DAFTAR ANGGOTA KELUARGA YANG MENJADI TANGGUNGAN | AM6: HALAMAN 3
N7: D. | O7: PENGHASILAN NETO DALAM NEGERI DAN PEKERJAAN
N8: E. | O8: DAFTAR BUKTI PEMOTONGAN/PEMUNGUTAN PPh
N9: NIK/NPWP | Q9: ='1'!J21 | R9: ='1'!K21 | S9: ='1'!L21 | T9: ='1'!M21 | U9: ='1'!N21 | V9: ='1'!O21 | W9: ='1'!P21 | X9: ='1'!Q21 | ... AF9: ='1'!Y21 | AM9: TAHUN PAJAK | AQ9: ='1'!E14 | AR9: ='1'!G14 | AS9: ='1'!I14 | AT9: ='1'!K14
C12: C. | D12: DAFTAR ANGGOTA KELUARGA YANG MENJADI TANGGUNGAN
AW13: -
C14: NAMA | M14: NIK | T14: TANGGAL LAHIR | AA14: HUBUNGAN DENGAN WAJIB PAJAK | AJ14: PEKERJAAN | AW14: Mengurus Rumah Tangga
AW15: Pelajar/Mahasiswa
C16: (1) | M16: (2) | T16: (3) | AA16: (4) | AJ16: (5) | AW16: Pensiunan
AA17: - | AW17: Anggota TNI/POLRI
AA18: - | AW18: Karyawan Swasta
AW19: Petani/Pekebun
AW20: Buruh Harian Lepas
AW21: Dokter
AA22: - | AJ22: - | AW22: Wirawasta
AA23: - | AJ23: - | AW23: Tidak Bekerja
C25: D. | D25: PENGHASILAN NETO DALAM NEGERI DARI PEKERJAAN
B27: HOME | C27: NO. | D27: NAMA PEMBERI KERJA | L27: NOMOR IDENTITAS PEMBERI KERJA | T27: PENGHASILAN BRUTO | AA27: PENGURANG PENGHASILAN BRUTO | AJ27: PENGHASILAN NETO
C29: (1) | D29: (2) | L29: (3) | T29: (4) | AA29: (5) | AJ29: (6)
AJ30: =T30-AA30 -> 0
C36: JUMLAH TABEL D | AH36: D | AJ36: =SUM(AJ30:AJ35) -> 0
AF37: PINDAHKAN JUMLAH TABEL D KE INDUK BAGIAN B ANGKA 1 HURUF a.
C38: E. | D38: DAFTAR BUKTI PEMOTONGAN/PEMUNGUTAN PPh
C40: NO. | D40: PEMOTONG/PEMUNGUT PPh | N40: BUKTI PEMOTONGAN/PEMUNGUTAN | V40: JENIS PAJAK | AA40: PENGHASILAN BRUTO | AM40: JUMLAH PPh YANG DIPOTONG/DIPUNGUT
C42: (1) | D42: (2) | N42: (3) | V42: (4) | AA42: (5) | AM42: (6) | AW42: -
D43: NIK/NPWP: | N43: NOMOR: | V43: - | AW43: PPh Pasal 21
D44: NAMA: | N44: TANGGAL: | AW44: PPh Pasal 22
D45: NIK/NPWP: | N45: NOMOR: | V45: - | AW45: PPh Pasal 23
D46: NAMA: | N46: TANGGAL: | AW46: PPh Pasal 26
D47: NIK/NPWP: | N47: NOMOR: | V47: - | AW47: PPh ditanggung pemerintah (DTP)
D48: NAMA: | N48: TANGGAL:
D49: NIK/NPWP: | N49: NOMOR: | V49: - | AW49: -
D50: NAMA: | N50: TANGGAL: | AW50: Anak
D51: NIK/NPWP: | N51: NOMOR: | V51: - | AW51: Cucu
D52: NAMA: | N52: TANGGAL: | AW52: Kepala Keluarga
D53: NIK/NPWP: | N53: NOMOR: | V53: - | AW53: Suami
D54: NAMA: | N54: TANGGAL: | AW54: Mertua
D55: NIK/NPWP: | N55: NOMOR: | V55: - | AW55: Pembantu
...

Sheet L2
D4: PERHATIAN: | N4: A. | O4: PENGHASILAN YANG DIKENAKAN PAJAK PENGHASILAN BERSIFAT FINAL | AM4: LAMPIRAN 2
D5: LAMPIRAN INI DIISI OLEH WAJIB PAJAK UNTUK MELAPORKAN PENGHASILAN YANG DIKENAKAN PPh YANG BERSIFAT FINAL, PENGHASILAN YANG TIDAK TERMASUK OBJEK PAJAK DAN/ATAU PENGHASILAN NETO LUAR NEGERI | N5: B. | O5: PENGHASILAN YANG TIDAK TERMASUK OBJEK PAJAK
N6: C. | O6: PENGHASILAN NETO LUAR NEGERI
N8: NIK/NPWP | Q8: ='1'!J21 | R8: ='1'!K21 | S8: ='1'!L21 | T8: ='1'!M21 | U8: ='1'!N21 | V8: ='1'!O21 | W8: ='1'!P21 | X8: ='1'!Q21 | ... AF8: ='1'!Y21 | AM8: TAHUN PAJAK | AQ8: ='1'!E14 | AR8: ='1'!G14 | AS8: ='1'!I14 | AT8: ='1'!K14
C11: A. | D11: PENGHASILAN YANG DIKENAKAN PAJAK PENGHASILAN BERSIFAT FINAL
C13: NO. | D13: PEMOTONG/PEMUNGUT PPh | N13: KODE | Q13: JENIS PENGHASILAN | Z13: DASAR PENGENAAN PAJAK | AI13: PPh TERUTANG | AW13: - | AX13: -
AW14: 28-423-01 | AX14: pemotongan/Pemungutan PPh final bagi WP dengan peredaran bruto tertentu
C15: (1) | D15: (2) | N15: (3) | Q15: (4) | Z15: (5) | AI15: (6) | AW15: 28-423-99 | AX15: PPh final sesuai PP-55/2022 (Disetor Sendiri)
C16: 1 | D16: NIK/NPWP: | N16: - | Q16: =VLOOKUP(N16,$AW$13:$AX$26,2,FALSE()) -> - | AW16: 28-404-01 | AX16: bunga tabungan dan bunga deposito yang ditempatkan di DN selain dari DHE)
D17: NAMA: | AW17: 28-401-01 | AX17: bunga obligasi, SUN, atau obligasi daerah yang diterima WP DN dan BUT
C18: 2 | D18: NIK/NPWP: | N18: - | Q18: =VLOOKUP(N18,$AW$13:$AX$26,2,FALSE()) -> - | AI18: =Z18*20% -> 0 | AW18: 28-406-01 | AX18: transaksi penjualan saham di bursa efek (bukan saham pendiri)
D19: NAMA: | AW19: 21-401-01 | AX19: uang pesangon yang dibayarkan sekaligus
C20: 3 | D20: NIK/NPWP: | N20: - | Q20: =VLOOKUP(N20,$AW$13:$AX$26,2,FALSE()) -> - | AI20: =Z20*10% -> 0 | AW20: 21-402-02 | AX20: honor atau imbalan lain APBN atau APBD yang diterima PNS/TNI/POLRI dan pensiunannya
D21: NAMA: | AW21: 28-405-01 | AX21: Hadiah Undian
C22: 4 | D22: NIK/NPWP: | N22: - | Q22: =VLOOKUP(N22,$AW$13:$AX$26,2,FALSE()) -> - | AI22: =Z22*10% -> 0 | AW22: 28-417-02 | AX22: bunga simpanan yang dibayarkan oleh koperasi kepada anggota WP OP
D23: NAMA: | AW23: 28-419-01 | AX23: dividen yang diterima/diperoleh WP OP DN
D24: NIK/NPWP: | N24: - | Q24: =VLOOKUP(N24,$AW$13:$AX$26,2,FALSE()) -> - | AW24: 28-402-01 | AX24: pengalihan hak atas tanah dan/atau bangunan
D25: NAMA: | AW25: 28-403-02 | AX25: persewaan tanah dan/atau bangunan
D26: NIK/NPWP: | N26: - | Q26: =VLOOKUP(N26,$AW$13:$AX$26,2,FALSE()) -> - | AW26: 28-409-10 | AX26: jasa konstruksi berupa jasa pelaksanaan konstruksi (kualifikasi usaha kecil)
D27: NAMA: | AW27: 28-499-99 | AX27: penghasilan istri dari satu pemberi kerja yang hak dan kewajiban perpajakannya dilaksanakan oleh kepala keluarga
D28: NIK/NPWP: | N28: - | Q28: =VLOOKUP(N28,$AW$13:$AX$26,2,FALSE()) -> -
D29: NAMA:
D30: NIK/NPWP: | N30: - | Q30: =VLOOKUP(N30,$AW$13:$AX$26,2,FALSE()) -> -
D31: NAMA:
D32: NIK/NPWP: | N32: - | Q32: =VLOOKUP(N32,$AW$13:$AX$26,2,FALSE()) -> -
D33: NAMA:
D34: NIK/NPWP: | N34: - | Q34: =VLOOKUP(N34,$AW$13:$AX$26,2,FALSE()) -> -
D35: NAMA:
D36: NIK/NPWP: | N36: - | Q36: =VLOOKUP(N36,$AW$13:$AX$26,2,FALSE()) -> -
D37: NAMA:
D38: NIK/NPWP: | N38: - | Q38: =VLOOKUP(N38,$AW$13:$AX$26,2,FALSE()) -> -
D39: NAMA:
D40: NIK/NPWP: | N40: - | Q40: =VLOOKUP(N40,$AW$13:$AX$26,2,FALSE()) -> -
D41: NAMA: | AV41: HOME
C42: JUMLAH TABEL A | X42: A | Z42: =SUM(Z16:Z40) -> 0 | AI42: =SUM(AI16:AI40) -> 0
AD43: PINDAHKAN JUMLAH TABEL A KOLOM (5) KE INDUK BAGIAN I ANGKA 14 HURUF c.
C45: B. | D45: PENGHASILAN YANG TIDAK TERMASUK OBJEK PAJAK
AY46: - | AZ46: -
C47: NO. | D47: KODE | M47: JENIS PENGHASILAN | V47: SUMBER PENGHASILAN | AL47: PENGHASILAN BRUTO | AY47: 303 | AZ47: Dividen atau bagian laba
V48: NIK/NPWP | AD48: NAMA | AY48: 401 | AZ48: Pembebasan utang
...

Sheet L3A-1
B4: HOME | D4: PERHATIAN: | O4: REKONSILIASI LAPORAN KEUANGAN (DAGANG) | AH4: LAMPIRAN 3A-1
D5: LAMPIRAN INI HARUS DIISI OLEH WAJIB PAJAK YANG MENYELENGGARAKAN PEMBUKUAN STELSEL KAS ATAU PEMBUKUAN STELSEL AKRUAL DI SEKTOR USAHA DAGANG
N8: NIK/NPWP | AH8: TAHUN PAJAK | AL8: ='1'!E14 | AM8: ='1'!G14 | AN8: ='1'!I14 | AO8: ='1'!K14
C11: A.1 | D11: LAPORAN LABA RUGI
C13: KODE AKUN | E13: NAMA AKUN | K13: NILAI KOMERSIAL | O13: TIDAK TERMASUK OBJEK PAJAK | S13: DIKENAKAN PPh FINAL | W13: OBJEK PAJAK TIDAK FINAL | AA13: PENYESUAIAN FISKAL POSITIF | AE13: PENYESUAIAN FISKAL NEGATIF | AI13: KODE PENYESUAIAN FISKAL | AM13: NILAI FISKAL
C16: (1) | E16: (2) | K16: (3) | O16: (4) | S16: (5) | W16: (6) | AA16: (7) | AE16: (8) | AI16: (9) | AM16: (10)
E17: PENJUALAN
C18: 4002 | E18: PENJUALAN DOMESTIK
C19: 4003 | E19: PENJUALAN EKSPOR
C20: 4004 | E20: PENJUALAN BRUTO
E21: DIKURANGI:
C22: 4011 | E22: RETUR
C23: 4012 | E23: POTONGAN PENJUALAN
C24: 4020 | E24: PENJUALAN BERSIH
E25: HARGA POKOK PENJUALAN:
C26: 5001 | E26: PEMBELIAN
C27: 5008 | E27: PERSEDIAAN AWAL
C28: 5009 | E28: DIKURANGI: PERSEDIAAN AKHIR
C29: 5020 | E29: JUMLAH HARGA POKOK PENJUALAN
C30: 4300 | E30: LABA KOTOR | AR30: FPO-01 | AS30: Biaya yang dibebankan/dikeluarkan untuk kepentingan pribadi Wajib Pajak atau orang yang menjadi tanggungannya
E31: BEBAN USAHA | AR31: FPO-02 | AS31: Premi Asuransi kesehatan, asuransi kecelakaan, asuransi jiwa, asuransi dwiguna, dan asuransi beasiswa yang dibayar oleh Wajib Pajak
C32: 5311 | E32: BEBAN GAJI, TUNJANGAN, BONUS, HONORARIUM, THR, DLL | AR32: FPO-04 | AS32: Jumlah yang melebihi kewajaran yang dibayarkan kepada pihak yang mempunyai hubungan istimewa sehubungan dengan pekerjaan yang dilakukan
C33: 5313 | E33: BEBAN TRANSPORTASI | AR33: FPO-05 | AS33: Harta yang dihibahkan, bantuan atau sumbangan
C34: 5314 | E34: BEBAN PENYUSUTAN DAN AMORTISASI | AR34: FPO-06 | AS34: Pajak penghasilan
C35: 5315 | E35: BEBAN SEWA | AR35: FPO-07 | AS35: Gaji yang dibayarkan kepada pemilik/orang yang menjadi tanggungannya
C36: 5316 | E36: BEBAN BUNGA | AR36: FPO-08 | AS36: Sanksi administrasi
C37: 5317 | E37: BEBAN SEHUBUNGAN DENGAN JASA | AR37: FPO-09 | AS37: Selisih penyusutan komersial di atas penyusutan fiskal
C38: 5318 | E38: BEBAN PIUTANG TIDAK TERTAGIH | AR38: FPO-10 | AS38: Selisih amortisasi komersial di atas amortisasi fiskal
C39: 5320 | E39: BEBAN PROMOSI/PEMASARAN | AR39: FPO-11 | AS39: Biaya untuk mendapatkan, menagih dan memelihara penghasilan yang dikenakan PPh Final dan penghasilan yang tidak termasuk objek pajak
C40: 5321 | E40: BEBAN ENTERTAINMENT | AR40: FPO-12 | AS40: Penyesuaian fiskal positif lainnya
C41: 5322 | E41: BEBAN UMUM DAN ADMINISTRASI | AR41: FNE-01 | AS41: Penghasilan yang dikenakan PPh final dan penghasilan yang tidak termasuk objek pajak tetapi termasuk dalam peredaran usaha
C42: 5399 | E42: BEBAN USAHA LAINNYA | AR42: FNE-02 | AS42: Selisih penyusutan komersial di bawah penyusutan fiska
C43: 5400 | E43: JUMLAH BEBAN USAHA | AR43: FNE-03 | AS43: Selisih amortisasi komersial di bawah amortisasi fiskal
C44: 4800 | E44: LABA (RUGI) SEBELUM PAJAK | AR44: FNE-04 | AS44: Penyesuaian fiskal negatif lainnya
X45: PINDAHKAN LABA (RUGI) SEBELUM PAJAK KOLOM (10) KE INDUK BAGIAN B ANGKA 1 HURUF b
C46: A.2 | D46: LAPORAN POSISI KEUANGAN (NERACA)
C48: KODE AKUN | E48: AKUN | W48: KODE AKUN | Y48: AKUN
C50: (1) | E50: (2) | W50: (1) | Y50: (2)
E51: ASET LANCAR | Y51: LIABILITAS JANGKA PENDEK | AR51: HOME
C52: 1101 | E52: KAS DAN SETARA KAS | W52: 2102 | Y52: UTANG USAHA - PIHAK KETIGA
...

Sheet L3A-2
B4: HOME | D4: PERHATIAN: | O4: REKONSILIASI LAPORAN KEUANGAN (JASA) | AH4: LAMPIRAN 3A-2
D5: LAMPIRAN INI HARUS DIISI OLEH WAJIB PAJAK YANG MENYELENGGARAKAN PEMBUKUAN STELSEL KAS ATAU PEMBUKUAN STELSEL AKRUAL DI SEKTOR USAHA JASA
N8: NIK/NPWP | AH8: TAHUN PAJAK | AL8: ='1'!E14 | AM8: ='1'!G14 | AN8: ='1'!I14 | AO8: ='1'!K14
C11: A.1 | D11: LAPORAN LABA RUGI
C13: KODE AKUN | E13: NAMA AKUN | K13: NILAI KOMERSIAL | O13: TIDAK TERMASUK OBJEK PAJAK | S13: DIKENAKAN PPh FINAL | W13: OBJEK PAJAK TIDAK FINAL | AA13: PENYESUAIAN FISKAL POSITIF | AE13: PENYESUAIAN FISKAL NEGATIF | AI13: KODE PENYESUAIAN FISKAL | AM13: NILAI FISKAL
C16: (1) | E16: (2) | K16: (3) | O16: (4) | S16: (5) | W16: (6) | AA16: (7) | AE16: (8) | AI16: (9) | AM16: (10)
E17: PENDAPATAN
C18: 4002 | E18: PENDAPATAN JASA
C19: 4003 | E19: BIAYA POKOK JASA
C20: 4004 | E20: LABA KOTOR | AR20: FPO-01 | AS20: Biaya yang dibebankan/dikeluarkan untuk kepentingan pribadi Wajib Pajak atau orang yang menjadi tanggungannya
E21: BEBAN USAHA | AR21: FPO-02 | AS21: Premi Asuransi kesehatan, asuransi kecelakaan, asuransi jiwa, asuransi dwiguna, dan asuransi beasiswa yang dibayar oleh Wajib Pajak
C22: 5311 | E22: BEBAN GAJI, TUNJANGAN, BONUS, HONORARIUM, THR, DLL | AR22: FPO-04 | AS22: Jumlah yang melebihi kewajaran yang dibayarkan kepada pihak yang mempunyai hubungan istimewa sehubungan dengan pekerjaan yang dilakukan
C23: 5313 | E23: BEBAN TRANSPORTASI | AR23: FPO-05 | AS23: Harta yang dihibahkan, bantuan atau sumbangan
C24: 5314 | E24: BEBAN PENYUSUTAN DAN AMORTISASI | AR24: FPO-06 | AS24: Pajak penghasilan
C25: 5315 | E25: BEBAN SEWA | AR25: FPO-07 | AS25: Gaji yang dibayarkan kepada pemilik/orang yang menjadi tanggungannya
C26: 5316 | E26: BEBAN BUNGA | AR26: FPO-08 | AS26: Sanksi administrasi
C27: 5317 | E27: BEBAN SEHUBUNGAN DENGAN JASA | AR27: FPO-09 | AS27: Selisih penyusutan komersial di atas penyusutan fiskal
C28: 5318 | E28: BEBAN PIUTANG TIDAK TERTAGIH | AR28: FPO-10 | AS28: Selisih amortisasi komersial di atas amortisasi fiskal
C29: 5320 | E29: BEBAN PROMOSI/PEMASARAN | AR29: FPO-11 | AS29: Biaya untuk mendapatkan, menagih dan memelihara penghasilan yang dikenakan PPh Final dan penghasilan yang tidak termasuk objek pajak
C30: 5321 | E30: BEBAN ENTERTAINMENT | AR30: FPO-12 | AS30: Penyesuaian fiskal positif lainnya
C31: 5322 | E31: BEBAN UMUM DAN ADMINISTRASI | AR31: FNE-01 | AS31: Penghasilan yang dikenakan PPh final dan penghasilan yang tidak termasuk objek pajak tetapi termasuk dalam peredaran usaha
C32: 5399 | E32: BEBAN USAHA LAINNYA | AR32: FNE-02 | AS32: Selisih penyusutan komersial di bawah penyusutan fiska
C33: 5400 | E33: JUMLAH BEBAN USAHA | AR33: FNE-03 | AS33: Selisih amortisasi komersial di bawah amortisasi fiskal
C34: 4800 | E34: LABA (RUGI) SEBELUM PAJAK | AR34: FNE-04 | AS34: Penyesuaian fiskal negatif lainnya
X35: PINDAHKAN LABA (RUGI) SEBELUM PAJAK KOLOM (10) KE INDUK BAGIAN B ANGKA 1 HURUF b
C36: A.2 | D36: LAPORAN POSISI KEUANGAN (NERACA)
C38: KODE AKUN | E38: AKUN | W38: KODE AKUN | Y38: AKUN
C40: (1) | E40: (2) | W40: (1) | Y40: (2)
E41: ASET LANCAR | Y41: LIABILITAS JANGKA PENDEK
C42: 1101 | E42: KAS DAN SETARA KAS | W42: 2102 | Y42: UTANG USAHA - PIHAK KETIGA | AR42: HOME
C43: 1200 | E43: INVESTASI | W43: 2103 | Y43: UTANG USAHA - PIHAK YANG MEMPUNYAI HUBUNGAN ISTIMEWA
C44: 1122 | E44: PIUTANG USAHA - PIHAK KETIGA | W44: 2111 | Y44: UTANG BANK
C45: 1123 | E45: PIUTANG USAHA - PIHAK YANG MEMPUNYAI HUBUNGAN ISTIMEWA | W45: 2191 | Y45: UTANG PAJAK
C46: 1124 | E46: PIUTANG LAINNYA - PIHAK KETIGA | W46: 2192 | Y46: UTANG DIVIDEN
C47: 1125 | E47: PIUTANG LAINNYA - PIHAK YANG MEMPUNYAI HUBUNGAN ISTIMEWA | W47: 2196 | Y47: BEBAN YANG MASIH HARUS DIBAYAR
C48: 1131 | E48: DIKURANGI: CADANGAN PIUTANG TAK TERTAGIH | W48: 2201 | Y48: UTANG BANK JANGKA PENDEK
C49: 1401 | E49: PERSEDIAAN | W49: 2202 | Y49: UTANG JANGKA PANJANG YANG JATUH TEMPO DALAM SATU TAHUN
C50: 1421 | E50: BEBAN DIBAYAR DI MUKA | W50: 2203 | Y50: UANG MUKA
C51: 1422 | E51: UANG MUKA | W51: 2228 | Y51: LIABILITAS JANGKA PENDEK LAINNYA
C52: 1423 | E52: PAJAK DIBAYAR DI MUKA | Y52: LIABILITAS JANGKA PANJANG
...

Sheet L3A-3
B4: HOME | D4: PERHATIAN: | O4: REKONSILIASI LAPORAN KEUANGAN (INDUSTRI) | AH4: LAMPIRAN 3A-1
D5: LAMPIRAN INI HARUS DIISI OLEH WAJIB PAJAK YANG MENYELENGGARAKAN PEMBUKUAN STELSEL KAS ATAU PEMBUKUAN STELSEL AKRUAL DI SEKTOR USAHA INDUSTRI
N8: NIK/NPWP | AH8: TAHUN PAJAK | AL8: ='1'!E14 | AM8: ='1'!G14 | AN8: ='1'!I14 | AO8: ='1'!K14
C11: A.1 | D11: LAPORAN LABA RUGI
C13: KODE AKUN | E13: NAMA AKUN | K13: NILAI KOMERSIAL | O13: TIDAK TERMASUK OBJEK PAJAK | S13: DIKENAKAN PPh FINAL | W13: OBJEK PAJAK TIDAK FINAL | AA13: PENYESUAIAN FISKAL POSITIF | AE13: PENYESUAIAN FISKAL NEGATIF | AI13: KODE PENYESUAIAN FISKAL | AM13: NILAI FISKAL
C16: (1) | E16: (2) | K16: (3) | O16: (4) | S16: (5) | W16: (6) | AA16: (7) | AE16: (8) | AI16: (9) | AM16: (10)
E17: PENJUALAN
C18: 4002 | E18: PENJUALAN DOMESTIK
C19: 4003 | E19: PENJUALAN EKSPOR
C20: 4004 | E20: PENJUALAN BRUTO
E21: DIKURANGI:
C22: 4011 | E22: RETUR
C23: 4012 | E23: POTONGAN PENJUALAN
C24: 4020 | E24: PENJUALAN BERSIH
C25: 5040 | E25: BIAYA BAHAN BAKU
C26: 5050 | E26: BIAYA TENAGA KERJA LANGSUNG
E27: BIAYA PABRIKASI | AR27: FPO-01 | AS27: Biaya yang dibebankan/dikeluarkan untuk kepentingan pribadi Wajib Pajak atau orang yang menjadi tanggungannya
C28: 5051 | E28: BIAYA TENAGA KERJA TIDAK LANGSUNG | AR28: FPO-02 | AS28: Premi Asuransi kesehatan, asuransi kecelakaan, asuransi jiwa, asuransi dwiguna, dan asuransi beasiswa yang dibayar oleh Wajib Pajak
C29: 5052 | E29: BIAYA PEMELIHARAAN DAN PERBAIKAN MESIN | AR29: FPO-04 | AS29: Jumlah yang melebihi kewajaran yang dibayarkan kepada pihak yang mempunyai hubungan istimewa sehubungan dengan pekerjaan yang dilakukan
C30: 5058 | E30: BIAYA PENYUSUTAN DAN AMORTISASI | AR30: FPO-05 | AS30: Harta yang dihibahkan, bantuan atau sumbangan
C31: 5059 | E31: BIAYA UTILITAS | AR31: FPO-06 | AS31: Pajak penghasilan
C32: 5069 | E32: BIAYA PABRIKASI LAINNNYA | AR32: FPO-07 | AS32: Gaji yang dibayarkan kepada pemilik/orang yang menjadi tanggungannya
C33: 5070 | E33: JUMLAH BIAYA PABRIKASI | AR33: FPO-08 | AS33: Sanksi administrasi
C34: 5080 | E34: JUMLAH BIAYA PRODUKSI | AR34: FPO-09 | AS34: Selisih penyusutan komersial di atas penyusutan fiskal
C35: 5090 | E35: PERSEDIAAN AWAL BARANG DALAM PROSES | AR35: FPO-10 | AS35: Selisih amortisasi komersial di atas amortisasi fiskal
C36: 5099 | E36: DIKURANGI: PERSEDIAAN AKHIR BARANG DALAM PROSES | AR36: FPO-11 | AS36: Biaya untuk mendapatkan, menagih dan memelihara penghasilan yang dikenakan PPh Final dan penghasilan yang tidak termasuk objek pajak
C37: 5100 | E37: JUMLAH HARGA POKOK PRODUKSI | AR37: FPO-12 | AS37: Penyesuaian fiskal positif lainnya
C38: 5008 | E38: PERSEDIAAN AWAL BARANG JADI | AR38: FNE-01 | AS38: Penghasilan yang dikenakan PPh final dan penghasilan yang tidak termasuk objek pajak tetapi termasuk dalam peredaran usaha
C39: 5009 | E39: DIKURANGI: PERSEDIAAN AKHIR BARANG JADI | AR39: FNE-02 | AS39: Selisih penyusutan komersial di bawah penyusutan fiska
... C41: 4300 | E41: LABA KOTOR | AR41: FNE-04 | AS41: Penyesuaian fiskal negatif lainnya
E42: BEBAN USAHA
C43: 5311 | E43: BEBAN GAJI, TUNJANGAN, BONUS, HONORARIUM, THR, DLL
C44: 5313 | E44: BEBAN TRANSPORTASI
C45: 5314 | E45: BEBAN PENYUSUTAN DAN AMORTISASI
C46: 5315 | E46: BEBAN SEWA
C47: 5316 | E47: BEBAN BUNGA
C48: 5317 | E48: BEBAN SEHUBUNGAN DENGAN JASA
C49: 5318 | E49: BEBAN PIUTANG TIDAK TERTAGIH
C50: 5320 | E50: BEBAN PROMOSI/PEMASARAN
C51: 5321 | E51: BEBAN ENTERTAINMENT
...

Sheet L3A-4
B4: HOME | D4: PERHATIAN: | N4: A. | O4: PENGHASILAN NETO DALAM NEGERI DARI USAHA DAN/ATAU PEKERJAAN BEBAS BERDASARKAN PENCATATAN | AM4: LAMPIRAN 3A-4
D5: LAMPIRAN INI HARUS DIISI OLEH WAJIB PAJAK YANG MENYELENGGARAKAN PENCATATAN DAN/ATAU MEMILIKI PENGHASILAN NETO DALAM NEGERI LAINNYA
N6: B. | O6: PENGHASILAN NETO DALAM NEGERI LAINNYA
N8: NIK/NPWP | Q8: ='1'!J21 | R8: ='1'!K21 | S8: ='1'!L21 | T8: ='1'!M21 | U8: ='1'!N21 | V8: ='1'!O21 | W8: ='1'!P21 | X8: ='1'!Q21 | ... AF8: ='1'!Y21 | AM8: TAHUN PAJAK | AQ8: ='1'!E14 | AR8: ='1'!G14 | AS8: ='1'!I14 | AT8: ='1'!K14
C11: A. | D11: PENGHASILAN NETO DALAM NEGERI DARI USAHA DAN/ATAU PEKEJAAN BEBAS BERDASARKAN PENCATATAN
C13: NO. | D13: NAMA TEMPAT KEGIATAN USAHA (TKU) | L13: JENIS USAHA / PEKERJAAN BEBAS | T13: PEREDARAN BRUTO | AA13: NORMA (%) | AJ13: PENGHASILAN NETO | BH13: -
BH14: Dagang
C15: (1) | D15: (2) | L15: (3) | T15: (4) | AA15: (5) | AJ15: (6) | BH15: Industri
C16: 1 | L16: - | T16: =L3B!BJ75 -> 0 | AJ16: =T16*AA16 -> 0 | BH16: Jasa
BH17: Pengacara
B18: L3B bagian C | BH18: Akuntan
BH19: Konsultan
BH20: Aktuaris
BH21: Notaris/PPAT
BH22: Dokter
BH23: Penilai
BH24: Arsitek
BH25: Artis dan profesi sejenisnya
AV26: HOME | BH26: Pembuat konten
C27: JUMLAH TABEL A | R27: A | T27: =SUM(T16:T26) -> 0 | AH27: A.6 | AJ27: =SUM(AJ16:AJ26) -> 0 | BH27: Penulis
AD28: PINDAHKAN JUMLAH TABEL A.6 KE INDUK BAGIAN B ANGKA 1 HURUF b. | BH28: Olahragawan
C29: B. | D29: PENGHASILAN NETO DALAM NEGERI LAINNYA | BH29: Pelatih/Pengajar
BH30: Distributor perusahaan pemasaran berjenjang
C31: NO. | D31: KODE | K31: KODE | AE31: PENGHASILAN NETO | BH31: Agen iklan
BH32: Agen asuransi
C33: (1) | D33: (2) | K33: (3) | AE33: (4) | AW33: - | AX33: - | BH33: Perantara
C34: 1 | D34: - | K34: =VLOOKUP(D34,$AW$33:$AX$47,2,FALSE()) -> - | AW34: 302 | AX34: Sewa harta selain tanah dan/atau bangunan | BH34: Usaha/profesi Lainnya
C35: 2 | D35: - | K35: =VLOOKUP(D35,$AW$33:$AX$47,2,FALSE()) -> - | AW35: 304 | AX35: Bunga
C36: 3 | D36: - | K36: =VLOOKUP(D36,$AW$33:$AX$47,2,FALSE()) -> - | AW36: 306 | AX36: Royalti
C37: 4 | D37: - | K37: =VLOOKUP(D37,$AW$33:$AX$47,2,FALSE()) -> - | AW37: 307 | AX37: Keuntungan karena penjualan atau karena pengalihan harta
C38: 5 | D38: - | K38: =VLOOKUP(D38,$AW$33:$AX$47,2,FALSE()) -> - | AW38: 314 | AX38: Imbalan bunga
C39: 6 | D39: - | K39: =VLOOKUP(D39,$AW$33:$AX$47,2,FALSE()) -> - | AW39: 319 | AX39: Keuntungan selisih kurs mata uang asing
C40: 7 | D40: - | K40: =VLOOKUP(D40,$AW$33:$AX$47,2,FALSE()) -> - | AW40: 399 | AX40: Penghasilan lain dari modal atau aset
C41: 8 | D41: - | K41: =VLOOKUP(D41,$AW$33:$AX$47,2,FALSE()) -> - | AW41: 401 | AX41: Pembebasan utang\
C42: 9 | D42: - | K42: =VLOOKUP(D42,$AW$33:$AX$47,2,FALSE()) -> - | AW42: 402 | AX42: Hibah
C43: 10 | D43: - | K43: =VLOOKUP(D43,$AW$33:$AX$47,2,FALSE()) -> - | AW43: 403 | AX43: Bantuan/sumbangan
C44: 11 | D44: - | K44: =VLOOKUP(D44,$AW$33:$AX$47,2,FALSE()) -> - | AW44: 407 | AX44: Klaim asuransi
C45: 12 | D45: - | K45: =VLOOKUP(D45,$AW$33:$AX$47,2,FALSE()) -> - | AW45: 408 | AX45: Beasiswa
C46: 13 | D46: - | K46: =VLOOKUP(D46,$AW$33:$AX$47,2,FALSE()) -> - | AW46: 409 | AX46: Hadiah
C47: 14 | D47: - | K47: =VLOOKUP(D47,$AW$33:$AX$47,2,FALSE()) -> - | AW47: 412 | AX47: Penghasilan dalam negeri lainnya
...

Sheet L3B
D4: PERHATIAN: | R4: REKAPITULASI PEREDARAN BRUTO | BG4: LAMPIRAN 3B
D5: LAMPIRAN INI DIISI OLEH WAJIB PAJAK YANG BERKEWAJIBAN MELAPORKAN RINCIAN REKAPITULASI PEREDARAN BRUTO
AB8: NIK/NPWP | AE8: ='1'!J21 | AF8: ='1'!K21 | AG8: ='1'!L21 | AH8: ='1'!M21 | AI8: ='1'!N21 | AJ8: ='1'!O21 | AK8: ='1'!P21 | AL8: ='1'!Q21 | ... AT8: ='1'!Y21 | BG8: TAHUN PAJAK | BK8: ='1'!E14 | BL8: ='1'!G14 | BM8: ='1'!I14 | BN8: ='1'!K14
C11: DAFTAR TEMPAT KEGIATAN USAHA (TKU)
C13: NO. | E13: ID TKU | M13: NAMA TKU | W13: ALAMAT | AF13: KELURAHAN/DESA | AO13: KECAMATAN | AW13: KOTA/KABUPATEN | BF13: PROVINSI
C15: (1) | E15: (2) | M15: (3) | W15: (4) | AF15: (5) | AO15: (6) | AW15: (7) | BF15: (8)
C16: 1
C21: A. | D21: REKAPITULASI PEREDARAN BRUTO UNTUK WAJIB PAJAK ORANG PRIBADI YANG MEMILIKI PEREDARAN BRUTO TERTENTU YANG DIKENAI PAJAK BERSIFAT FINAL
C23: NO. | D23: NAMA TKU | N23: JANUARI | R23: FEBRUARI | V23: MARET | Z23: APRIL | AD23: MEI | AH23: JUNI | AL23: JULI | AP23: AGUSTUS | AT23: SEPTEMBER | AX23: OKTOBER | BB23: NOPEMBER | BF23: DESEMBER | BJ23: JUMLAH
C24: (1) | D24: (2) | N24: (3) | R24: (4) | V24: (5) | Z24: (6) | AD24: (7) | AH24: (8) | AL24: (9) | AP24: (10) | AT24: (11) | AX24: (12) | BB24: (13) | BF24: (14) | BJ24: (15)
C25: 1 | D25: =M16 | BJ25: =SUM(N25:BF25) -> 0
BJ26: =SUM(N26:BF26) -> 0
BJ27: =SUM(N27:BF27) -> 0
C28: a. | D28: JUMLAHPEREDARAN BRUTO | N28: =SUM(N25:N27) -> 0 | R28: =SUM(R25:R27) -> 0 | V28: =SUM(V25:V27) -> 0 | Z28: =SUM(Z25:Z27) -> 0 | AD28: =SUM(AD25:AD27) -> 0 | AH28: =SUM(AH25:AH27) -> 0 | AL28: =SUM(AL25:AL27) -> 0 | AP28: =SUM(AP25:AP27) -> 0 | AT28: =SUM(AT25:AT27) -> 0 | AX28: =SUM(AX25:AX27) -> 0 | BB28: =SUM(BB25:BB27) -> 0 | BF28: =SUM(BF25:BF27) -> 0 | BJ28: =SUM(BJ25:BJ27) -> 0
C30: b. | D30: AKUMULASI PEREDARAN BRUTO | N30: =N28 -> 0 | R30: =R28+N30 -> 0 | V30: =V28+R30 -> 0 | Z30: =Z28+V30 -> 0 | AD30: =AD28+Z30 -> 0 | AH30: =AH28+AD30 -> 0 | AL30: =AL28+AH30 -> 0 | AP30: =AP28+AL30 -> 0 | AT30: =AT28+AP30 -> 0 | AX30: =AX28+AT30 -> 0 | BB30: =BB28+AX30 -> 0 | BF30: =BF28+BB30 -> 0 | BJ30: =BF30 -> 0
C32: c. | D32: PEREDARAN BRUTO TIDAK KENA PAJAK | N32: 500000000 | BJ32: =N32 -> 500000000
C34: d. | D34: PEREDARAN BRUTO KENA PAJAK | N34: =IF(N30>=500000000,(N28-500000000),0) -> 0 | R34: =IF(R28<=500000000,IF(SUM(N28:U29)>500000000,R28,0),R28) -> 0 | V34: =IF(SUM(N28:U29)<=500000000,IF(SUM(N28:Y29)>500000000,(SUM(N28:Y29)-500000000),0),V28) -> 0 | Z34: =IF(SUM(N28:Y29)<=500000000,IF(SUM(N28:AC29)>500000000,(SUM(N28:AC29)-500000000),0),Z28) -> 0 | AD34: =IF(SUM(N28:AC29)<=500000000,IF(SUM(N28:AG29)>500000000,(SUM(N28:AG29)-500000000),0),AD28) -> 0 | AH34: =IF(SUM(N28:AG29)<=500000000,IF(SUM(N28:AK29)>500000000,(SUM(N28:AK29)-500000000),0),AH28) -> 0 | AL34: =IF(SUM(N28:AK29)<=500000000,IF(SUM(N28:AO29)>500000000,(SUM(N28:AO29)-500000000),0),AL28) -> 0 | AP34: =IF(SUM(N28:AO29)<=500000000,IF(SUM(N28:AS29)>500000000,(SUM(N28:AS29)-500000000),0),AP28) -> 0 | AT34: =IF(SUM(N28:AS29)<=500000000,IF(SUM(N28:AW29)>500000000,(SUM(N28:AW29)-500000000),0),AT28) -> 0 | AX34: =IF(SUM(N28:AW29)<=500000000,IF(SUM(N28:BA29)>500000000,(SUM(N28:BA29)-500000000),0),AX28) -> 0 | BB34: =IF(SUM(N28:BA29)<=500000000,IF(SUM(N28:BE29)>500000000,(SUM(N28:BE29)-500000000),0),BB28) -> 0 | BF34: =IF(SUM(N28:BE29)<=500000000,IF(SUM(N28:BI29)>500000000,(SUM(N28:BI29)-500000000),0),BF28) -> 0 | BJ34: =SUM(N34:BI35) -> 0
C36: e. | D36: JUMLAH PPh FINAL TERUTANG (0,5 % X d) | N36: =N34*0.5/100 -> 0 | R36: =R34*0.5/100 -> 0 | V36: =V34*0.5/100 -> 0 | Z36: =Z34*0.5/100 -> 0 | AD36: =AD34*0.5/100 -> 0 | AH36: =AH34*0.5/100 -> 0 | AL36: =AL34*0.5/100 -> 0 | AP36: =AP34*0.5/100 -> 0 | AT36: =AT34*0.5/100 -> 0 | AX36: =AX34*0.5/100 -> 0 | BB36: =BB34*0.5/100 -> 0 | BF36: =BF34*0.5/100 -> 0 | BJ36: =SUM(N36:BI37) -> 0
C38: f. | D38: JUMLAH PPh FINAL YANG DISETOR SENDIRI | N38: 0 | R38: 0 | V38: =V36 -> 0 | Z38: =Z36 -> 0 | AD38: =AD36 -> 0 | AH38: =AH36 -> 0 | AL38: =AL36 -> 0 | AP38: =AP36 -> 0 | AT38: =AT36 -> 0 | AX38: =AX36 -> 0 | BB38: =BB36 -> 0 | BF38: =BF36 -> 0 | BJ38: =SUM(N38:BI39) -> 0
C40: g. | D40: JUMLAH PPh FINAL YANG DIPOTONG/DIPUNGUT PIHAK LAIN | N40: 0 | R40: 0 | V40: 0 | Z40: 0 | AD40: 0 | AH40: 0 | AL40: 0 | AP40: 0 | AT40: 0 | AX40: 0 | BB40: 0 | BF40: 0 | BJ40: =SUM(N40:BI41) -> 0
C42: h. | D42: SELISIH (e - f - g ) | N42: =N36-N38-N40 -> 0 | R42: =R36-R38-R40 -> 0 | V42: =V36-V38-V40 -> 0 | Z42: =Z36-Z38-Z40 -> 0 | AD42: =AD36-AD38-AD40 -> 0 | AH42: =AH36-AH38-AH40 -> 0 | AL42: =AL36-AL38-AL40 -> 0 | AP42: =AP36-AP38-AP40 -> 0 | AT42: =AT36-AT38-AT40 -> 0 | AX42: =AX36-AX38-AX40 -> 0 | BB42: =BB36-BB38-BB40 -> 0 | BF42: =BF36-BF38-BF40 -> 0 | BJ42: =SUM(N42:BI43) -> 0
C44: i. | D44: SELSIH PADA SPT YANG DIBETULKAN | BJ44: =SUM(N44:BI45) -> 0
BP45: LAMPIRAN 2
C46: j. | D46: SELISIH KARENA PEMBETULAN (h - i) | BJ46: =SUM(N46:BI47) -> 0
D48: PINDAHKAN HURUF f JUMLAH PPh FINAL YANG DISETOR SENDIRI KOLOM (15) KE LAMPIRAN 2 BAGIAN A DENGAN KODE 28-423-99 JENIS PENGHASILAN "PENGHASILAN YANG DIKENAKAN PAJAK BERSIFAT FINAL SESUAI PERATURAN PEMERINTAH NOMOR 55 TAHUN 2022 (DISETOR SENDIRI)"
D50: PINDAHKAN HURUF g. JUMLAH PPh FINAL YANG DIPOTONG/DIPUNGUT PIHAK LAIN PADA KOLOM (3) SAMPAI (14) KE LAMPIRAN 2 BAGIAN A SESUAI DENGAN BUKTI PEMOTONGAN/PEMUNGUTAN PPh
C52: B. | D52: REKAPITULASI PEREDARAN BRUTO UNTUK WAJIB PAJAK ORANG PRIBADI PENGUSAHA TERTENTU (OPPT)
C54: METODE PEMBUKUAN | M54: 1. | N54: PENCATATAN | T54: 2. | U54: PEMBUKUAN STELSEL KAS ATAU PEMBUKUAN STELSEL AKRUAL
C56: NO. | D56: NAMA TKU | K56: METODE PEMBUKUAN | N56: JANUARI | R56: FEBRUARI | V56: MARET | Z56: APRIL | AD56: MEI | AH56: JUNI | AL56: JULI | AP56: AGUSTUS | AT56: SEPTEMBER | AX56: OKTOBER | BB56: NOVEMBER | BF56: DESEMBER | BJ56: JUMLAH
C58: (1) | D58: (2) | K58: (3) | N58: (4) | R58: (5) | V58: (6) | Z58: (7) | AD58: (8) | AH58: (9) | AL58: (10) | AP58: (11) | AT58: (12) | AX58: (13) | BB58: (14) | BF58: (15) | BJ58: (16)
BJ59: =SUM(N59:BF59) -> 0
BJ60: =SUM(N60:BF60) -> 0
BJ61: =SUM(N61:BF61) -> 0
C62: JUMLAH PEREDARAN BRUTO | N62: =SUM(N59:N61) -> 0 | R62: =SUM(R59:R61) -> 0 | V62: =SUM(V59:V61) -> 0 | Z62: =SUM(Z59:Z61) -> 0 | AD62: =SUM(AD59:AD61) -> 0 | AH62: =SUM(AH59:AH61) -> 0 | AL62: =SUM(AL59:AL61) -> 0 | AP62: =SUM(AP59:AP61) -> 0 | AT62: =SUM(AT59:AT61) -> 0 | AX62: =SUM(AX59:AX61) -> 0 | BB62: =SUM(BB59:BB61) -> 0 | BF62: =SUM(BF59:BF61) -> 0 | BJ62: =SUM(N62:BF62) -> 0 | BP62: HOME
C63: JUMLAH PPh | N63: =N62*0.75/100 -> 0 | R63: =R62*0.75/100 -> 0 | V63: =V62*0.75/100 -> 0 | Z63: =Z62*0.75/100 -> 0 | AD63: =AD62*0.75/100 -> 0 | AH63: =AH62*0.75/100 -> 0 | AL63: =AL62*0.75/100 -> 0 | AP63: =AP62*0.75/100 -> 0 | AT63: =AT62*0.75/100 -> 0 | AX63: =AX62*0.75/100 -> 0 | BB63: =BB62*0.75/100 -> 0 | BF63: =BF62*0.75/100 -> 0 | BJ63: =SUM(N63:BF63) -> 0
D64: JIKA METODE PEMBUKUAN ADALAH 1. PENCATATAN, PINDAHKAN SELURUH DATA PADA MASING-MASING TKU DARI KOLOM (1) SAMPAI KOLOM (16) PADA TABEL B KE TABEL C LAMPIRAN INI. BARIS JUMLAH PPh PADA KOLOM (4) SAMPAI DENGAN KOLOM (16) DIGABUNGKAN DENGAN JUMLAH PPh PADA TABEL C BARIS JUMLAH PPh SESUAI DENGAN KOLOM MASING-MASING.
D66: JIKA METODE PEMBUKUAN ADALAH 2. PEMBUKUAN STELSEL KAS ATAU PEMBUKUAN STELSEL AKRUAL, PINDAHKAN JUMLAH PEREDARAN BRUTO KOLOM (16) KE LAMPIRAN 3A-1/3A-2/3A-3 BAGIAN A.1. DAN JUMLAH PPh KOLOM (16) KE INDUK BAGIAN D ANGKA 10 HURUF b
C69: C. | D69: REKAPITULASI PEREDARAN BRUTO UNTUK PENGGUNA NORMA PENGHITUNGAN PENGHASILAN NETO (NPPN)
C71: NO. | D71: NAMA TKU | K71: JENIS USAHA/ PEKERJAAN BEBAS | N71: JANUARI | R71: FEBRUARI | V71: MARET | Z71: APRIL | AD71: MEI | AH71: JUNI | AL71: JULI | AP71: AGUSTUS | AT71: SEPTEMBER | AX71: OKTOBER | BB71: NOVEMBER | BF71: DESEMBER | BJ71: JUMLAH
C74: (1) | D74: (2) | K74: (3) | N74: (4) | R74: (5) | V74: (6) | Z74: (7) | AD74: (8) | AH74: (9) | AL74: (10) | AP74: (11) | AT74: (12) | AX74: (13) | BB74: (14) | BF74: (15) | BJ74: (16)
...

Sheet L3C
B4: HOME | D4: PERHATIAN: | X4: DAFTAR PENYUSUTAN DAN AMORTISASI FISKAL | AW4: LAMPIRAN 3C
D5: LAMPIRAN INI DIISI OLEH WAJIB PAJAK YANG MEMBEBANKAN BIAYA PENYUSUTAN DAN/ATAU AMORTISASI
W8: NIK/NPWP | AZ8: TAHUN PAJAK | BE8: ='1'!E14 | BF8: ='1'!G14 | BG8: ='1'!I14 | BH8: ='1'!K14
C11: A.1 | D11: LAPORAN LABA RUGI
C13: KODE HARTA | F13: KELOMPOK / JENIS HARGA | N13: BULAN / TAHUN PEROLEHAN | S13: HARGA PEROLEHAN (RUPIAH) | AA13: NILAI SISA BUKU FISKAL AWAL TAHUN (RUPIAH) | AI13: METODE PENYUSUTAN / AMORTISASI | AS13: PENYUSUTAN / AMORTISASI FISKAL PADA TAHUN INI (RUPIAH) | BB13: KETERANGAN | BK13: - | BL13: -
BK14: 0401 | BL14: Sepeda
AI15: KOMERSIAL | AN15: FISKAL | BK15: 0402 | BL15: Motor
C16: (1) | F16: (2) | N16: (3) | S16: (4) | AA16: (5) | AI16: (6) | AN16: (7) | AS16: (8) | BB16: (9) | BK16: 0403 | BL16: Mobil Penumpang
F17: I. | G17: HARTA BERWUJUD | BK17: 0404 | BL17: Bus
G18: A. | H18: KELOMPOK 1 | BK18: 0405 | BL18: Kendaraan Angkutan
H19: 1. | I19: …................................... | BK19: 0406 | BL19: Kendaraan Khusus
H20: 2. | I20: …................................... | BK20: 0407 | BL20: Kereta
H21: 3 | I21: …................................... | BK21: 0408 | BL21: Pesawat Terbang
G22: B. | H22: KELOMPOK 2 | BK22: 0409 | BL22: Kapal Laut
H23: 1. | I23: …................................... | BK23: 0410 | BL23: Mesin
H24: 2. | I24: …................................... | BK24: 0411 | BL24: Cart
H25: 3 | I25: …................................... | BK25: 0412 | BL25: Kapal Pesiar
G26: C. | H26: KELOMPOK 3 | BK26: 0413 | BL26: Peralatan
H27: 1. | I27: …................................... | BK27: 0499 | BL27: Aset Bergerak Lainnya
H28: 2. | I28: …................................... | BK28: 0707 | BL28: Peralatan Olahraga Khusus
H29: 3 | I29: …................................... | BK29: 0708 | BL29: Peralatan Elektronik
G30: D. | H30: KELOMPOK 4 | BK30: 0709 | BL30: Rumah Tangga/Furnitur
H31: 1. | I31: …................................... | BK31: 0710 | BL31: Peralatan Lainnya
H32: 2. | I32: …................................... | BK32: 0711 | BL32: Jet Ski
H33: 3 | I33: …................................... | BK33: 0799 | BL33: Aset Lainnya
G34: E. | H34: KELOMPOK LAINNYA | BK34: - | BL34: - | BX34: - | BY34: -
H35: 1. | I35: …................................... | BK35: Garis Lurus | BX35: 0502 | BY35: Bangunan untuk tempat tinggal
H36: 2. | I36: …................................... | BK36: Jumlah Angka Tahunan | BX36: 0503 | BY36: Bangunan untuk usaha (toko, pabrik, kantor, gudang dan sejenisnya)
H37: 3 | I37: …................................... | BK37: Saldo Menurun | BX37: 0504 | BY37: Bangunan yang disewakan
F38: II. | G38: BANGUNAN | BK38: Saldo Menurun Ganda | BX38: 0505 | BY38: Apartemen
G39: A. | H39: PERMANEN | BK39: Jumlah Jam Masa | BX39: 0599 | BY39: Aset tidak bergerak lainnya
H40: 1. | I40: …................................... | BK40: Jumlah Satuan Produksi
H41: 2. | I41: …................................... | BK41: Metode Lainnya
H42: 3 | I42: …................................... | BK42: - | BL42: -
G43: B. | H43: TIDAK PERMANEN | BK43: GL/Straight Line (Garis Lurus)
H44: 1. | I44: …................................... | BK44: JSP/Number of Production Unit (Jumlah Satuan Produksi)
H45: 2. | I45: …................................... | BK45: SM/Declining Method (Saldo Menurun)
C46: A. | D46: JUMLAH PENYUSUTAN FISKAL | BK46: - | BL46: -
C47: B. | D47: JUMLAH PENYUSUTAN KOMERSIAL | BK47: 0601 | BL47: Paten
C48: C. | D48: SELISIH PENYUSUTAN (A-B) | BK48: 0602 | BL48: Royalti
...

Sheet L3D
D4: PERHATIAN: | AM4: LAMPIRAN 3D
D5: LAMPIRAN INI DIISI OLEH WAJJIB PAJAK YANG MEMBEBANKAN BIAYA ENTERTAINMENT, BIAYA PROMOSI DAN PENJUALAN, SERTA PENGGANTIAN ATAU IMBALAN DALAM BENTUK NANTURA DAN/ATAU KENIKMATAN DAN/ATAU DAFTAR PIUTANG YANG NYATA-NYATA TIDAK DAPAT DITAGIH | N5: RINCIAN BIAYA TERTENTU
P10: NIK/NPWP | T10: ='1'!J21 | U10: ='1'!K21 | V10: ='1'!L21 | W10: ='1'!M21 | X10: ='1'!N21 | Y10: ='1'!O21 | Z10: ='1'!P21 | AA10: ='1'!Q21 | ... AI10: ='1'!Y21
AM11: TAHUN PAJAK | AQ11: ='1'!E14 | AR11: ='1'!G14 | AS11: ='1'!I14 | AT11: ='1'!K14
C14: A. | D14: DAFTAR NOMINATIF BIAYA ENTERTAINMENT
C16: NO. | E16: PEMBERIAN ENTERTAINMENT | AA16: RELASI USAHA YANG DIBERIKAN ENTERTAINMENT | AR16: KETERANGAN
E17: TANGGAL | H17: NAMA TEMPAT | N17: ALAMAT | S17: JENIS | W17: JUMLAH | AA17: NAMA | AE17: POSISI | AI17: NAMA PERUSAHAAN | AN17: JENIS USAHA
C18: (1) | E18: (2) | H18: (3) | N18: (4) | S18: (5) | W18: (6) | AA18: (7) | AE18: (8) | AI18: (9) | AN18: (10) | AR18: (11)
AW24: HOME
C28: B. | D28: DAFTAR NOMINATIF BIAYA PROMOSI SERTA PENGGANTIAN ATAU IMBALAN DALAM BENTUK NATURA DAN/ATAU KENIKMATAN
C30: NO. | E30: DATA PENERIMA | AK30: PEMOTONGAN/PEMUNGUTAN PPh
E31: NOMOR IDENTITAS | J31: NAMA | N31: ALAMAT | S31: TANGGAL | V31: BENTUK DAN JENIS BIAYA | AB31: NILAI | AF31: KETERANGAN | AK31: JUMLAH | AQ31: NOMOR BUKTI POTONG
C32: (1) | E32: (2) | J32: (3) | N32: (4) | S32: (5) | V32: (6) | AB32: (7) | AF32: (8) | AK32: (9) | AQ32: (10)
AW39: HOME
C42: C. | D42: DAFTAR PIUTANG YANG NYATA-NYATA TIDAK DAPAT DITAGIH
C44: NO. | E44: NOMOR IDENTITAS | K44: NAMA DEBITUR | P44: ALAMAT | U44: JUMLAH PLAFON PIUTANG | AA44: JUMLAH PIUTANG YANG NYATA-NYATA TIDAK DAPAT DITAGIH | AG44: METODE PEMBEBANAN | AM44: JENIS DOKUMEN PEMBUKTIAN PEMENUHAN PERSYARATAN
C47: (1) | E47: (2) | K47: (3) | P47: (4) | U47: (5) | AA47: (6) | AG47: (7) | AM47: (8)
AW48: -
AW49: Beban Langsung
AW50: Beban Cadangan
AW52: -
AW53: Penyerahan Perkara
AW54: Perjanjian Tertulis
AW55: Publikasi Penerbitan
AW56: Pengakuan Debitur
AQ57: HOME

Sheet L4
D4: PERHATIAN: | N4: A. | O4: PENGHITUNGAN ANGSURAN PPh PASAL 25 TAHUN PAJAK BERIKUTNYA | AM4: LAMPIRAN 4
D5: LAMPIRAN INI DIISI OLEH WAJIB PAJAK YANG BERKEWAJIBAN MEMBAYAR ANGSURAN PPh PASAL 25 DAN/ATAU WAJIB PAJAK YANG STATUS KEWAJIBAN PAJAK WAJIB PAJAK DAN PASANGANNYA ADALAH PISAH HARTA (PH) ATAU MEMILIH TERPISAH (MT) | N5: B. | O5: PENGHITUNGAN PPh TERUTANG WAJIB PAJAK DAN SUAMI/ISTRI
Q8: NIK/NPWP | T8: ='1'!J21 | U8: ='1'!K21 | V8: ='1'!L21 | W8: ='1'!M21 | X8: ='1'!N21 | Y8: ='1'!O21 | Z8: ='1'!P21 | AA8: ='1'!Q21 | ... AI8: ='1'!Y21
AM9: TAHUN PAJAK | AQ9: ='1'!E14 | AR9: ='1'!G14 | AS9: ='1'!I14 | AT9: ='1'!K14
C12: A. | D12: PENGHITUNGAN ANGSURAN PPh PASAL 25 TAHUN PAJAK BERIKUTNYA
D14: 1 | F14: PENGHASILAN NETO | AM14: ='1'!AL75 -> 0
D16: 2 | F16: KOMPENSASI KERUGIAN TAHUN PAJAK SEBELUMNYA | AM16: ='L5'!AZ30 -> 0
D18: 3 | F18: ZAKAT/SUMBANGAN KEAGAMAAN YANG BERSIFAT WAJIB | AM18: ='1'!AL77 -> 0
D20: 4 | F20: JUMLAH PENGHASILAN NETO | X20: ( | Y20: 1 | Z20: - | AA20: 2 | AB20: - | AC20: 3 | AD20: ) | AM20: =AM14-AM16-AM18 -> 0
AW21: - | AX21: 0
D22: 5 | F22: PENGHASILAN TIDAK KENA PAJAK | Y22: - | AM22: =VLOOKUP(Y22,AW21:AX33,2,FALSE()) -> 0 | AW22: TK/0 | AX22: 54000000
AW23: TK/1 | AX23: 58500000
D24: 6 | F24: PENGHASILAN KENA PAJAK | X24: ( | Y24: 4 | Z24: - | AA24: 5 | AB24: ) | AM24: =AM20-AM22 -> 0 | AW24: TK/2 | AX24: 63000000
AW25: TK/3 | AX25: 67500000
D26: 7 | F26: PPh TERUTANG | AM26: =(5%*60000000)+(15%*190000000)+(25%*(267000000-250000000)) -> 35750000 | AW26: K/0 | AX26: 58500000
AW27: K/1 | AX27: 63000000
D28: 8 | F28: PENGURANG PPh TERUTANG | AM28: 0 | AW28: K/2 | AX28: 67500000
AW29: K/3 | AX29: 72000000
D30: 9 | F30: KREDIT PAJAK | AM30: ='1'!AL98 -> 0 | AW30: K/I/0 | AX30: 112500000
AW31: K/I/1 | AX31: 117000000
D32: 10 | F32: PPh YANG HARUS DIBAYAR | X32: ( | Y32: 7 | Z32: - | AA32: 8 | AB32: - | AC32: 9 | AD32: ) | AM32: =AM26-AM28-AM30 -> 35750000 | AW32: K/I/2 | AX32: 121500000
AW33: K/I/3 | AX33: 126000000
D34: 11 | F34: ANGSURAN PPh PASAL 25 TAHUN PAJAK BERIKUTNYA | X34: ( | Y34: 1/12 | AA34: X | AC34: 10 | AD34: ) | AM34: =1/12*AM32 -> 2979166.7
R37: PINDAHKAN JUMLAH ANGSURAN PPh PASAL 25 TAHUN PAJAK BERIKUTNYA PADA NOMOR 11 KE INDUK BAGIAN H ANGKA 13 HURUF b
C39: B. | D39: PENGHITUNGAN PPh TERUTANG WAJIB PAJAK DAN SUAMI/ISTRI
AH41: WAJIB PAJAK | AO41: SUAMI/ISTRI
D43: 1 | F43: PENGHASILAN BRUTO
D45: 2 | F45: PENGHASILAN NETO
D47: 3 | F47: PENGHASILAN NETO SETELAH DIKURANGI ZAKAT/SUMBANGAN KEAGAMAAN WAJIB DAN KOMPENSASI KERUGIAN | AG47: 3a | AN47: 3b
D49: 4 | F49: PENGHASILAN NETO SETELAH DIKURANGI ZAKAT/SUMBANGAN KEAGAMAAN WAJIB DAN KOMPENSASI KERUGIAN GABUNGAN | AG49: =AH47+AO47 -> 0
D51: 5 | F51: PENGHASILAN TIDAK KENA PAJAK GABUNGAN | Y51: K/I/0
D53: 6 | F53: PENGHASILAN KENA PAJAK GABUNGAN | Y53: ( | Z53: 4 | AA53: - | AB53: 5 | AC53: ) | AG53: =AG49-AG51 -> 0
D55: 7 | F55: PPh TERUTANG GABUNGAN
D57: 8 | F57: PPh TERUTANG YANG DI TANGGUNG WAJIB PAJAK | W57: {[ | X57: 3a | Y57: : | Z57: 4 | AA57: ] | AB57: X | AC57: 7 | AD57: } | AG57: =(AH47/AG49)*AG55 -> #DIV/0!
D59: 9 | F59: PPh TERUTANG YANG DITANGGUNG OLEH SUAMI/ISTRI | W59: {[ | X59: 3b | Y59: : | Z59: 4 | AA59: ] | AB59: X | AC59: 7 | AD59: } | AG59: =(AO47/AG49)*AG55 -> #DIV/0!
P64: PINDAHKAN JUMLAH PPh TERUTANG YANG DITANGGUNG OLEH WAJIB PAJAK PADA NOMOR 8 KE INDUK BAGIAN C ANGKA 7 SPT WAJIB PAJAK
P65: PINDAHKAN JUMLAH PPh TERUTANG YANG DITANGGUNG OLEH SUAMI/ISTRI PADA NOMOR 9 KE INDUK BAGIAN C ANGKA 7 SPT SUAMI/ISTRI
D67: WAJIB PAJAK
AE69: NAMA DAN TTD
D70: NIK/NPWP
...

Sheet L5
D4: PERHATIAN: | W4: A. | X4: PENGHITUNGAN KOMPENSASI KERUGIAN FISKAL | AZ4: LAMPIRAN 5
D5: LAMPIRAN INI DIISI OLEH WAJIB PAJAK YANG MENGAKUI KOMPENSASI KERUGIAN FISKAL,PENGURANG PENGHASILAN NETO, DAN/ATAU PENGURANG PPh TERUTANG | W5: B. | X5: PENGURANG PENGHASILAN NETO
W6: C. | X6: PENGURANG PPh TERUTANG
W8: NIK/NPWP | Z8: ='1'!J21 | AA8: ='1'!K21 | AB8: ='1'!L21 | AC8: ='1'!M21 | AD8: ='1'!N21 | AE8: ='1'!O21 | AF8: ='1'!P21 | AG8: ='1'!Q21 | ... AO8: ='1'!Y21 | AZ8: TAHUN PAJAK | BD8: ='1'!E14 | BE8: ='1'!G14 | BF8: ='1'!I14 | BG8: ='1'!K14
C11: A. | D11: PENGHITUNGAN KOMPENSASI KERUGIAN FISKAL
C13: NO. | D13: LABA/RUGI NETO FISKAL | L13: KOMPENSASI KERUGIAN FISKAL
M15: TAHUN | O15: 2 | P15: 0 | Q15: 2 | R15: 1 | U15: TAHUN | W15: 2 | X15: 0 | Y15: 2 | Z15: 2 | AC15: TAHUN | AE15: 2 | AF15: 0 | AG15: 2 | AH15: 3 | AK15: TAHUN | AM15: 2 | AN15: 0 | AO15: 2 | AP15: 4 | AS15: TAHUN | AU15: 2 | AV15: 0 | AW15: 2 | AX15: 5 | BA15: TAHUN | BC15: 2 | BD15: 0 | BE15: 2 | BF15: 6
D16: TAHUN PAJAK | H16: RUPIAH
L17: RUPIAH | T17: RUPIAH | AB17: RUPIAH | AJ17: RUPIAH | AR17: RUPIAH | AZ17: RUPIAH
AR18: (TAHUN PAJAK INI) | AZ18: (TAHUN PAJAK BERJALAN)
C19: (1) | D19: (2) | H19: (3) | L19: (4) | T19: (5) | AB19: (6) | AJ19: (7) | AR19: (8) | AZ19: (9)
C20: 1 | L20: 0 | T20: 0 | AB20: 0 | AJ20: 0 | AR20: 0
C21: 2 | L21: 0 | T21: 0 | AB21: 0 | AJ21: 0 | AR21: 0
C22: 3 | L22: 0 | T22: 0 | AB22: 0 | AJ22: 0 | AR22: 0 | AZ22: 0
C23: 4 | L23: 0 | T23: 0 | AB23: 0 | AJ23: 0 | AR23: 0
C24: 5 | L24: 0 | T24: 0 | AB24: 0 | AJ24: 0 | AR24: 0
C25: 6 | L25: 0 | T25: 0 | AB25: 0 | AJ25: 0 | AR25: 0
C26: 7
C27: 8
C28: 9
C29: 10
C30: JUMLAH TABEL A | J30: A | L30: =SUM(L20:L29) -> 0 | T30: =SUM(T20:T29) -> 0 | AB30: =SUM(AB20:AB29) -> 0 | AJ30: =SUM(AJ20:AJ29) -> 0 | AR30: =SUM(AR20:AR29) -> 0 | AZ30: =SUM(AZ20:AZ29) -> 0
AJ31: PINDAHKAN JUMLAH TABEL A KOLOM (8) KE LAMPIRAN INI BAGIAN B BARIS 6 KOLOM (4)
C33: B. | D33: PENGURANG PENGHASILAN BRUTO | AB33: C. | AC33: PENGURANG PPh TERUTANG
C35: NO. | D35: KODE | I35: JENIS PENGURANG PENGHASILAN NETO | R35: JUMLAH PENGURANG PENGHASILAN NETO | AB35: NO. | AC35: KODE | AH35: JENIS PENGURANG PPh TERUTANG | AQ35: JUMLAH PENGURANG PPh TERUTANG
A37: - | B37: - | C37: (1) | D37: (2) | I37: (3) | R37: (4) | AB37: (1) | AC37: (2) | AH37: (3) | AQ37: (4) | AZ37: - | BA37: -
A38: 501 | B38: Zakat | C38: 1 | D38: - | I38: =VLOOKUP(D38,$A$37:$B$42,2,FALSE()) -> - | AB38: 1 | AC38: - | AH38: =VLOOKUP(AC38,$AZ$37:$BA$39,2,FALSE()) -> - | AQ38: 0 | AZ38: 506 | BA38: Fasilitas pembebasan atau pengurang PPh (Tax Holiday)
A39: 502 | B39: Sumbangan Keagamaan | C39: 2 | D39: - | I39: =VLOOKUP(D39,$A$37:$B$42,2,FALSE()) -> - | AB39: 2 | AC39: - | AH39: =VLOOKUP(AC39,$AZ$37:$BA$39,2,FALSE()) -> - | AQ39: 0 | AZ39: 505 | BA39: Pengurang PPh Lainnya
A40: 503 | B40: Fasilitas Pengurang Penghasilan Kena Pajak (Tax Allowance) | C40: 3 | D40: - | I40: =VLOOKUP(D40,$A$37:$B$42,2,FALSE()) -> - | AB40: 3 | AC40: - | AH40: =VLOOKUP(AC40,$AZ$37:$BA$39,2,FALSE()) -> - | AQ40: 0
A41: 504 | B41: Fasilitas keringanan pajak lainnya (Tax Reliefs) | C41: 4 | D41: - | I41: =VLOOKUP(D41,$A$37:$B$42,2,FALSE()) -> - | AB41: 4 | AC41: - | AH41: =VLOOKUP(AC41,$AZ$37:$BA$39,2,FALSE()) -> - | AQ41: 0
A42: 505 | B42: Pengurang Penghasilan Neto Lainnya | C42: 5 | D42: JUMLAH TABEL B | P42: B.5 | R42: =SUM(R38:R41) -> 0 | AB42: 5 | AC42: - | AH42: =VLOOKUP(AC42,$AZ$37:$BA$39,2,FALSE()) -> - | AQ42: 0
C43: 6 | D43: JUMLAH KOMPENSASI KERUGIAN FISKAL | P43: B.6 | R43: =AR30 -> 0 | AB43: 6 | AC43: - | AH43: =VLOOKUP(AC43,$AZ$37:$BA$39,2,FALSE()) -> - | AQ43: 0
C44: 7 | D44: JUMLAH PENGURANG PENGHASILAN NETO (B.5 + B.6) | P44: B.7 | R44: =R42+R43 -> 0 | AB44: 7 | AC44: JUMLAH TABEL C | AO44: C | AQ44: =SUM(AQ38:AQ43) -> 0
C45: PINDAHKAN JUMLAH PENGURANG PENGHASILAN NETO (B.7) DI BARIS 7 KOLOM (4) KE INDUK BAGIAN C ANGKA 3
AU46: HOME

Sheet Sheet1
B3: Imbalan kepada Bukan Pegawai Lainnya yang mendapat fasilitas di daerah tertentu
B4: Upah Pegawai Tidak Tetap yang Dibayarkan secara Harian, Mingguan, Satuan dan Borongan dengan Penghasilan Bruto sampai dengan Rp2.500.000 Sehari yang Mendapat Fasilitas di Daerah Tertentu
B5: Upah Pegawai Tidak Tetap yang Dibayarkan secara Harian, Mingguan, Satuan dan Borongan dengan Penghasilan Bruto lebih dari Rp2.500.000 Sehari yang Mendapat Fasilitas di Daerah Tertentu
B6: Penghasilan yang Diterima atau Diperoleh Pegawai Tetap yang Menerima Fasilitas di Daerah Tertentu
B7: Uang Pesangon yang Dibayarkan Sekaligus
B8: Uang Manfaat Pensiun, Tunjangan Hari Tua atau Jaminan Hari Tua dan Pembayaran Sejenis yang Dibayarkan Sekaligus
B9: Honor dan Imbalan Lain yang Dibebankan Dibebankan kepada APBN atau APBD yang Diterima oleh PNS, Anggota TNI/POLRI, Pejabat Negara dan Pensiunannya (LAMA)
B10: Honor atau Imbalan Lain yang Dibebankan kepada APBN atau APBD yang Diterima oleh PNS Golongan III, Anggota TNI dan Anggota POLRI Golongan Pangkat Perwira Pertama, dan pensiunannya
B11: Honor atau Imbalan Lain yang Dibebankan kepada APBN atau APBD yang Diterima oleh Pejabat Negara, PNS Golongan IV, Anggota TNI dan Anggota POLRI Golongan Pangkat Perwira Menengah dan Perwira Tinggi, dan Pensiunannya
B12: Honor atau Imbalan Lain yang Dibebankan kepada APBN atau APBD yang Diterima oleh PNS Golongan I dan Golongan II, Anggota TNI dan Anggota POLRI Golongan Pangkat Tamtama dan Bintara, dan Pensiunannya
B13: Objek PPh Pasal 21 yang Bersifat Final Lainnya
B14: Penghasilan Sehubungan dengan Transaksi Penjualan Barang, Penyerahan Jasa, dan/atau Persewaan serta Penghasilan Lain Sehubungan dengan Penggunaan Harta yang Dilakukan Melalui Pihak Lain dalam Sistem Informasi Pengadaan Pemerintah (Final)
... B101: Penghasilan Final Lainnya
